
<!-- This URDF was automatically created by SolidWorks to URDF Exporter! Originally created by Stephen Brawner (brawner@gmail.com) 
     Commit Version: 1.6.0-4-g7f85cfe  Build Version: 1.6.7995.38578
     For more information, please see http://wiki.ros.org/sw_urdf_exporter -->
<robot
  name="rover_assembly_description">

  <link name="dummy_link" />
  <joint name="dummy_joint" type="fixed">
    <parent link="dummy_link"/>
    <child link="base_link"/>
  </joint>

  <link
    name="base_link">
    <inertial>
      <origin
        xyz="0.0065233 -6.9841E-05 0.0049949"
        rpy="0 0 0" />
      <mass
        value="0.20594" />
      <inertia
        ixx="0.00023282"
        ixy="9.7737E-09"
        ixz="2.4315E-05"
        iyy="0.00027419"
        iyz="-7.3118E-09"
        izz="0.00041916" />
    </inertial>
    <visual>
      <origin
        xyz="0 0 0"
        rpy="0 0 0" />
      <geometry>
        <mesh
          filename="package://rover_assembly_description/meshes/base_link.STL" />
      </geometry>
      <material
        name="">
        <color
          rgba="1 0.94902 0.9098 1" />
      </material>
    </visual>
    <collision>
      <origin
        xyz="0 0 0"
        rpy="0 0 0" />
      <geometry>
        <mesh
          filename="package://rover_assembly_description/meshes/base_link.STL" />
      </geometry>
    </collision>
  </link>
  <link
    name="left_wheel_link">
    <inertial>
      <origin
        xyz="2.7908E-07 -3.2347E-08 -0.12902"
        rpy="0 0 0" />
      <mass
        value="0.029734" />
      <inertia
        ixx="1.2291E-05"
        ixy="6.5019E-11"
        ixz="9.0896E-11"
        iyy="1.2291E-05"
        iyz="-7.735E-12"
        izz="2.0379E-05" />
    </inertial>
    <visual>
      <origin
        xyz="0 0 0"
        rpy="0 0 0" />
      <geometry>
        <mesh
          filename="package://rover_assembly_description/meshes/left_wheel_link.STL" />
      </geometry>
      <material
        name="">
        <color
          rgba="0.29804 0.29804 0.29804 1" />
      </material>
    </visual>
    <collision>
      <origin
        xyz="0 0 0"
        rpy="0 0 0" />
      <geometry>
        <mesh
          filename="package://rover_assembly_description/meshes/left_wheel_link.STL" />
      </geometry>
    </collision>
  </link>
  <joint
    name="left_wheel_joint "
    type="continuous">
    <origin
      xyz="-0.030862 0.060664 0.00024787"
      rpy="1.5698 0 3.1407" />
    <parent
      link="base_link" />
    <child
      link="left_wheel_link" />
    <axis
      xyz="0 0 1" />
  </joint>
  <link
    name="right_wheel_link">
    <inertial>
      <origin
        xyz="0.00012042 0.000129 -0.12891"
        rpy="0 0 0" />
      <mass
        value="0.029734" />
      <inertia
        ixx="1.2291E-05"
        ixy="-5.2953E-12"
        ixz="-7.6632E-09"
        iyy="1.2291E-05"
        iyz="-8.1079E-09"
        izz="2.0379E-05" />
    </inertial>
    <visual>
      <origin
        xyz="0 0 0"
        rpy="0 0 0" />
      <geometry>
        <mesh
          filename="package://rover_assembly_description/meshes/right_wheel_link.STL" />
      </geometry>
      <material
        name="">
        <color
          rgba="0.29804 0.29804 0.29804 1" />
      </material>
    </visual>
    <collision>
      <origin
        xyz="0 0 0"
        rpy="0 0 0" />
      <geometry>
        <mesh
          filename="package://rover_assembly_description/meshes/right_wheel_link.STL" />
      </geometry>
    </collision>
  </link>
  <joint
    name="right_wheel_joint"
    type="continuous">
    <origin
      xyz="-0.030976 -0.060483 0.00012661"
      rpy="1.5708 0 0" />
    <parent
      link="base_link" />
    <child
      link="right_wheel_link" />
    <axis
      xyz="0.00093633 0.001001 -1" />
  </joint>
  <link
    name="lidar_link">
    <inertial>
      <origin
        xyz="-3.4037E-05 0.011952 0.016735"
        rpy="0 0 0" />
      <mass
        value="0.0782" />
      <inertia
        ixx="2.5804E-05"
        ixy="2.47E-07"
        ixz="2.7479E-09"
        iyy="2.0961E-05"
        iyz="-4.5845E-07"
        izz="4.4317E-05" />
    </inertial>
    <visual>
      <origin
        xyz="0 0 0"
        rpy="0 0 0" />
      <geometry>
        <mesh
          filename="package://rover_assembly_description/meshes/lidar_link.STL" />
      </geometry>
      <material
        name="">
        <color
          rgba="1 1 1 0.35" />
      </material>
    </visual>
    <collision>
      <origin
        xyz="0 0 0"
        rpy="0 0 0" />
      <geometry>
        <mesh
          filename="package://rover_assembly_description/meshes/lidar_link.STL" />
      </geometry>
    </collision>
  </link>
  <joint
    name="lidar_joint"
    type="fixed">
    <origin
      xyz="-0.010767 4.1541E-05 0.03054"
      rpy="-0.035801 0 -1.5997" />
    <parent
      link="base_link" />
    <child
      link="lidar_link" />
    <axis
      xyz="0 0 0" />
  </joint>
  <link
    name="castor_link">
    <inertial>
      <origin
        xyz="0 0 0"
        rpy="0 0 0" />
      <mass
        value="0.2" />
      <inertia
        ixx="0"
        ixy="0"
        ixz="0"
        iyy="0"
        iyz="0"
        izz="0" />
    </inertial>
    <visual>
      <origin
        xyz="0 0 0"
        rpy="0 0 0" />
      <geometry>
        <mesh
          filename="package://rover_assembly_description/meshes/castor_link.STL" />
      </geometry>
      <material
        name="">
        <color
          rgba="1 1 1 1" />
      </material>
    </visual>
    <collision>
      <origin
        xyz="0 0 0"
        rpy="0 0 0" />
      <geometry>
        <mesh
          filename="package://rover_assembly_description/meshes/castor_link.STL" />
      </geometry>
    </collision>
  </link>
  <joint
    name="castor_joint"
    type="fixed">
    <origin
      xyz="0.038053 -0.0069786 -0.013058"
      rpy="-0.0010351 -0.035786 -3.1416" />
    <parent
      link="base_link" />
    <child
      link="castor_link" />
    <axis
      xyz="0.99975 0.02249 0" />
  </joint>
  <gazebo reference="castor_link">
    <mu1>0.0</mu1>
    <mu2>0.0</mu2>
    <kp>1000000.0</kp>
    <kd>100.0</kd>
    <material>Gazebo/Grey</material>
  </gazebo>
</robot>