<?xml version="1.0" ?>
<robot name="final_assemble_rover" xmlns:xacro="http://www.ros.org/wiki/xacro">

    <!-- ROOT LINK -->
    <link name="base_footprint"/>
    <joint name="base_footprint_joint" type="fixed">
        <parent link="base_footprint"/>
        <child link="base_link"/>
        <origin xyz="0 0 0.1" rpy="1.5708 0 0"/> 
    </joint>

    <xacro:include filename="$(find final_assemble_rover_description)/urdf/materials.xacro" />
    <xacro:include filename="$(find final_assemble_rover_description)/urdf/final_assemble_rover.trans" />
    <xacro:include filename="$(find final_assemble_rover_description)/urdf/final_assemble_rover.gazebo" />
    <xacro:include filename="$(find final_assemble_rover_description)/urdf/gazebo_control.xacro" />  

    <!-- CHASSIS -->
    <link name="base_link">
        <inertial>
            <!-- ZEROED CENTER OF MASS SO IT DOESN'T TIP -->
            <origin xyz="0 0 0" rpy="0 0 0"/>
            <mass value="1.0"/>
            <inertia ixx="0.01" ixy="0.0" ixz="0.0" iyy="0.01" iyz="0.0" izz="0.01" />  
        </inertial>
        <visual>
            <origin xyz="0 0 0" rpy="0 0 0"/>
            <geometry>
                <mesh filename="file://$(find final_assemble_rover_description)/meshes/base_link.stl" />
            </geometry>
            <material name="red"/>
        </visual>
        <!-- BELLY FIX: Shifted up and shrunk so it can't touch the floor -->
        <collision>
            <origin xyz="0 0.05 0" rpy="0 0 0"/>
            <geometry>
                <box size="0.1 0.05 0.08"/> 
            </geometry>
        </collision>
    </link>

    <!-- RIGHT WHEEL -->
    <link name="right_wheel_link_1_1">
        <inertial>
            <origin xyz="0 0 0" rpy="0 0 0"/>
            <mass value="0.1"/>
            <inertia ixx="0.001" ixy="0.0" ixz="0.0" iyy="0.001" iyz="0.0" izz="0.001" />  
        </inertial>
        <visual>
            <!-- EXACT ORIGINAL FUSION OFFSET -->
            <origin xyz="0.029 -0.025 -0.06121" rpy="0 0 0"/>
            <geometry>
                <mesh filename="file://$(find final_assemble_rover_description)/meshes/right_wheel_link_1_1.stl" />
            </geometry>
            <material name="silver"/>
        </visual>
        <collision>
            <origin xyz="0 0 0" rpy="0 0 0"/>
            <geometry>
                <cylinder radius="0.035" length="0.02"/>
            </geometry>
        </collision>
    </link>
    <joint name="Revolute 19" type="continuous">
        <!-- EXACT ORIGINAL JOINT OFFSET -->
        <origin xyz="-0.029 0.025 0.06121" rpy="0 0 0"/>
        <parent link="base_link"/>
        <child link="right_wheel_link_1_1"/>
        <axis xyz="0.0 0.0 -1.0"/>
    </joint>

    <!-- LEFT WHEEL -->
    <link name="left_wheel_link_1_1">
        <inertial>
            <origin xyz="0 0 0" rpy="0 0 0"/>
            <mass value="0.1"/>
            <inertia ixx="0.001" ixy="0.0" ixz="0.0" iyy="0.001" iyz="0.0" izz="0.001" />  
        </inertial>
        <visual>
            <!-- EXACT ORIGINAL FUSION OFFSET -->
            <origin xyz="0.029 -0.025 0.06121" rpy="0 0 0"/>
            <geometry>
                <mesh filename="file://$(find final_assemble_rover_description)/meshes/left_wheel_link_1_1.stl" />
            </geometry>
            <material name="silver"/>
        </visual>
        <collision>
            <origin xyz="0 0 0" rpy="0 0 0"/>
            <geometry>
                <cylinder radius="0.035" length="0.02"/>
            </geometry>
        </collision>
    </link>
    <joint name="Revolute 20" type="continuous">
        <!-- EXACT ORIGINAL JOINT OFFSET -->
        <origin xyz="-0.029 0.025 -0.06121" rpy="0 0 0"/>
        <parent link="base_link"/>
        <child link="left_wheel_link_1_1"/>
        <axis xyz="0.0 0.0 -1.0"/>
    </joint>

    <!-- CASTOR WHEEL -->
    <link name="castor_link_1_1">
        <inertial>
            <origin xyz="0 0 0" rpy="0 0 0"/>
            <mass value="0.01"/>
            <inertia ixx="0.0001" ixy="0.0" ixz="0.0" iyy="0.0001" iyz="0.0" izz="0.0001" />  
        </inertial>
        <visual>
            <!-- EXACT ORIGINAL FUSION OFFSET -->
            <origin xyz="-0.039746 0.0076 0.0" rpy="0 0 0"/>
            <geometry>
                <mesh filename="file://$(find final_assemble_rover_description)/meshes/castor_link_1_1.stl"/>
            </geometry>
            <material name="silver"/>
        </visual>
        <collision>
            <origin xyz="0 0 0" rpy="0 0 0"/>
            <geometry>
                <!-- TINY RADIUS SO IT DOESN'T JACK UP THE ROVER -->
                <sphere radius="0.002"/>
            </geometry>
        </collision>
    </link>
    <joint name="Rigid 21" type="fixed">
        <!-- EXACT ORIGINAL JOINT OFFSET -->
        <origin xyz="0.039746 -0.0076 0.0" rpy="0 0 0"/>
        <parent link="base_link"/>
        <child link="castor_link_1_1"/>
    </joint>

    <!-- LASER SENSOR -->
    <link name="laser_link_1_1">
        <inertial>
            <origin xyz="0 0 0" rpy="0 0 0"/>
            <mass value="0.01"/>
            <inertia ixx="0.0001" ixy="0.0" ixz="0.0" iyy="0.0001" iyz="0.0" izz="0.0001" />  
        </inertial>
        <visual>
            <!-- EXACT ORIGINAL FUSION OFFSET -->
            <origin xyz="0.0025 -0.09965 -0.0" rpy="0 0 0"/>
            <geometry>
                <mesh filename="file://$(find final_assemble_rover_description)/meshes/laser_link_1_1.stl"/>
            </geometry>
            <material name="silver"/>
        </visual>
        <collision>
            <origin xyz="0 0 0" rpy="0 0 0"/>
            <geometry>
                <box size="0.03 0.03 0.03"/>
            </geometry>
        </collision>
    </link>
    <joint name="Rigid 22" type="fixed">
        <origin xyz="-0.0025 0.09965 0.0" rpy="0 0 0"/>
        <parent link="base_link"/>
        <child link="laser_link_1_1"/>
    </joint>

</robot>