<?xml version="1.0"?>
<robot xmlns:xacro="http://www.ros.org/wiki/xacro" name="final_assemble_rover">

    <!-- INERTIA MACROS (To prevent the Gazebo physics explosions) -->
    <xacro:macro name="box_inertia" params="m w h d">
        <inertial>
            <mass value="${m}"/>
            <inertia ixx="${(m/12) * (h*h + d*d)}" ixy="0.0" ixz="0.0" iyy="${(m/12) * (w*w + d*d)}" iyz="0.0" izz="${(m/12) * (w*w + h*h)}"/>
        </inertial>
    </xacro:macro>

    <xacro:macro name="cylinder_inertia" params="m r h">
        <inertial>
            <mass value="${m}"/>
            <inertia ixx="${(m/12) * (3*r*r + h*h)}" ixy="0.0" ixz="0.0" iyy="${(m/12) * (3*r*r + h*h)}" iyz="0.0" izz="${(m/2) * (r*r)}"/>
        </inertial>
    </xacro:macro>

    <xacro:macro name="sphere_inertia" params="m r">
        <inertial>
            <mass value="${m}"/>
            <inertia ixx="${(2/5) * m * (r*r)}" ixy="0.0" ixz="0.0" iyy="${(2/5) * m * (r*r)}" iyz="0.0" izz="${(2/5) * m * (r*r)}"/>
        </inertial>
    </xacro:macro>

    <!-- BASE FOOTPRINT (Ground Level) -->
    <link name="base_footprint"/>

    <!-- CHASSIS (12cm x 11cm x 5cm) -->
    <joint name="base_joint" type="fixed">
        <parent link="base_footprint"/>
        <child link="base_link"/>
        <origin xyz="0 0 0.055" rpy="0 0 0"/>
    </joint>

    <link name="base_link">
        <visual>
            <geometry>
                <box size="0.12 0.11 0.05"/>
            </geometry>
            <material name="red"><color rgba="0.8 0.1 0.1 1.0"/></material>
        </visual>
        <collision>
            <geometry>
                <box size="0.12 0.11 0.05"/>
            </geometry>
        </collision>
        <xacro:box_inertia m="1.0" w="0.12" h="0.11" d="0.05"/>
    </link>
    <gazebo reference="base_link"><material>Gazebo/Red</material></gazebo>

    <!-- LEFT WHEEL (Radius 3cm, Width 2.5cm) -->
    <joint name="left_wheel_joint" type="continuous">
        <parent link="base_link"/>
        <child link="left_wheel"/>
        <origin xyz="-0.035 0.0675 -0.025" rpy="-1.5708 0 0"/>
        <axis xyz="0 0 1"/>
    </joint>

    <link name="left_wheel">
        <visual>
            <geometry>
                <cylinder radius="0.03" length="0.025"/>
            </geometry>
            <material name="black"><color rgba="0.1 0.1 0.1 1.0"/></material>
        </visual>
        <collision>
            <geometry>
                <cylinder radius="0.03" length="0.025"/>
            </geometry>
        </collision>
        <xacro:cylinder_inertia m="0.2" r="0.03" h="0.025"/>
    </link>
    <gazebo reference="left_wheel"><material>Gazebo/Black</material></gazebo>

    <!-- RIGHT WHEEL (Radius 3cm, Width 2.5cm) -->
    <joint name="right_wheel_joint" type="continuous">
        <parent link="base_link"/>
        <child link="right_wheel"/>
        <origin xyz="-0.035 -0.0675 -0.025" rpy="1.5708 0 0"/>
        <axis xyz="0 0 -1"/>
    </joint>

    <link name="right_wheel">
        <visual>
            <geometry>
                <cylinder radius="0.03" length="0.025"/>
            </geometry>
            <material name="black"/>
        </visual>
        <collision>
            <geometry>
                <cylinder radius="0.03" length="0.025"/>
            </geometry>
        </collision>
        <xacro:cylinder_inertia m="0.2" r="0.03" h="0.025"/>
    </link>
    <gazebo reference="right_wheel"><material>Gazebo/Black</material></gazebo>

    <!-- CASTOR WHEEL (Radius 2cm) -->
    <joint name="castor_joint" type="fixed">
        <parent link="base_link"/>
        <child link="castor_wheel"/>
        <origin xyz="0.04 0 -0.035" rpy="0 0 0"/>
    </joint>

    <link name="castor_wheel">
        <visual>
            <geometry>
                <sphere radius="0.02"/>
            </geometry>
            <material name="white"><color rgba="0.9 0.9 0.9 1.0"/></material>
        </visual>
        <collision>
            <geometry>
                <sphere radius="0.02"/>
            </geometry>
        </collision>
        <xacro:sphere_inertia m="0.1" r="0.02"/>
    </link>
    <!-- ZERO FRICTION TAG: Prevents castor from dragging in Gazebo -->
    <gazebo reference="castor_wheel">
        <material>Gazebo/White</material>
        <mu1>0.001</mu1>
        <mu2>0.001</mu2>
    </gazebo>

    <!-- VIRTUAL LIDAR PUCK -->
    <joint name="lidar_joint" type="fixed">
        <parent link="base_link"/>
        <child link="lidar_link"/>
        <origin xyz="0 0 0.045" rpy="0 0 0"/>
    </joint>

    <link name="lidar_link">
        <visual>
            <geometry>
                <cylinder radius="0.03" length="0.04"/>
            </geometry>
            <material name="black"/>
        </visual>
        <collision>
            <geometry>
                <cylinder radius="0.03" length="0.04"/>
            </geometry>
        </collision>
        <xacro:cylinder_inertia m="0.1" r="0.03" h="0.04"/>
    </link>
    <gazebo reference="lidar_link"><material>Gazebo/Black</material></gazebo>

    <!-- GAZEBO DIFFERENTIAL DRIVE PLUGIN -->
    <gazebo>
        <plugin name="diff_drive" filename="libgazebo_ros_diff_drive.so">
            <ros>
                <namespace>/</namespace>
            </ros>
            <left_joint>left_wheel_joint</left_joint>
            <right_joint>right_wheel_joint</right_joint>
            <wheel_separation>0.135</wheel_separation>
            <wheel_diameter>0.06</wheel_diameter>
            <max_wheel_torque>20</max_wheel_torque>
            <max_wheel_acceleration>1.0</max_wheel_acceleration>
            <publish_odom>true</publish_odom>
            <publish_odom_tf>true</publish_odom_tf>
            <publish_wheel_tf>true</publish_wheel_tf>
            <odometry_frame>odom</odometry_frame>
            <robot_base_frame>base_footprint</robot_base_frame>
        </plugin>
    </gazebo>

    <!-- GAZEBO VIRTUAL LIDAR PLUGIN (Feeds map data to Nav2) -->
    <gazebo reference="lidar_link">
        <sensor type="ray" name="virtual_lidar">
            <pose>0 0 0 0 0 0</pose>
            <visualize>true</visualize>
            <update_rate>10</update_rate>
            <ray>
                <scan>
                    <horizontal>
                        <samples>360</samples>
                        <resolution>1</resolution>
                        <min_angle>-3.14159</min_angle>
                        <max_angle>3.14159</max_angle>
                    </horizontal>
                </scan>
                <range>
                    <min>0.15</min>
                    <max>12.0</max>
                    <resolution>0.01</resolution>
                </range>
            </ray>
            <plugin name="scan" filename="libgazebo_ros_ray_sensor.so">
                <ros>
                    <remapping>~/out:=scan</remapping>
                </ros>
                <output_type>sensor_msgs/LaserScan</output_type>
                <frame_name>lidar_link</frame_name>
            </plugin>
        </sensor>
    </gazebo>
</robot>
